Workbook

Sheet 00_Huong_dan
A1: UAT EMAIL REVERIFY — HƯỚNG DẪN CHẠY
A2: Nguồn | B2: LOCAL SRS v3.5: Docs-PM-HTPLDN/_bmad-output/planning-artifacts/srs-v3.5
A3: Ngày tạo | B3: 2026-08-12
A4: Nguyên tắc Pass | B4: Chỉ Pass khi mọi Expected theo bước đạt qua UI/API/Gmail + đúng To/CC + mailbox âm không nhận + chuông đúng nếu SRS yêu cầu in-app; queue/SMTP/audit chỉ kiểm khi có quyền.
A5: Fail | B5: Một expected theo SRS không đạt, kể cả email tới inbox nhưng state/count/recipient/content/audit/SLA sai.
A6: Blocked | B6: Thiếu BA decision hoặc oracle môi trường; tuyệt đối không đổi thành Pass.
A7: Trình tự | B7: 1) 00 Hướng dẫn → 2) Test Data → 3) Dev Setup → 4) Tài khoản → 5) Doanh nghiệp → 6) Notification → 7) SMTP/Security/NFR → 8) Traceability/Summary.
A8: Mailbox DEV | B8: Dùng duy nhất Gmail thật diupt01@gmail.com để lấy OTP và kiểm thông báo. Tìm đúng alias bằng query to:<alias> + mốc thời gian/subject trong sheet 06_Test_Data.
A9: Dev setup | B9: Sheet 07_Dev_Setup ghi mapping đã áp dụng/read-back và đúng mục còn cần dev xử lý. Không seed lại các record đã tồn tại.
A10: Đăng nhập fixture | B10: Dev cung cấp mật khẩu/cách đăng nhập và trạng thái 2FA qua kênh bảo mật; không ghi mật khẩu thật vào workbook/evidence.
A11: Kiểm tra alias | B11: Trong Gmail query to:<alias>, mở Show details/Show original và đối chiếu To/CC + timestamp/message-id. Không Pass chỉ vì thấy thư trong inbox chung.
A12: Evidence tối thiểu | B12: Ảnh UI/chuông + raw email/MIME hoặc message-id + API response; timestamp event/SMTP khi test SLA nếu có quyền.
A13: Bảo mật | B13: Không đưa mật khẩu thật hoặc token đầy đủ vào evidence/workbook.

Sheet 01_Tong_hop
A1: Nhóm | B1: Tổng TC | C1: P0 | D1: P1 | E1: Not Run | F1: Pass | G1: Fail | H1: Blocked | I1: Pass rate (đã run)
A2: Tài khoản | B2: =COUNTA('02_Tai_khoan'!B2:B50) | C2: =COUNTIF('02_Tai_khoan'!E2:E50,"P0") | D2: =COUNTIF('02_Tai_khoan'!E2:E50,"P1") | E2: =COUNTIF('02_Tai_khoan'!U2:U50,"Not Run") | F2: =COUNTIF('02_Tai_khoan'!U2:U50,"Pass") | G2: =COUNTIF('02_Tai_khoan'!U2:U50,"Fail") | H2: =COUNTIF('02_Tai_khoan'!U2:U50,"Blocked") | I2: =IFERROR(F2/(F2+G2),0)
A3: Doanh nghiệp | B3: =COUNTA('03_Doanh_nghiep'!B2:B30) | C3: =COUNTIF('03_Doanh_nghiep'!E2:E30,"P0") | D3: =COUNTIF('03_Doanh_nghiep'!E2:E30,"P1") | E3: =COUNTIF('03_Doanh_nghiep'!U2:U30,"Not Run") | F3: =COUNTIF('03_Doanh_nghiep'!U2:U30,"Pass") | G3: =COUNTIF('03_Doanh_nghiep'!U2:U30,"Fail") | H3: =COUNTIF('03_Doanh_nghiep'!U2:U30,"Blocked") | I3: =IFERROR(F3/(F3+G3),0)
A4: Notification | B4: =COUNTA('04_Notification'!B2:B75) | C4: =COUNTIF('04_Notification'!E2:E75,"P0") | D4: =COUNTIF('04_Notification'!E2:E75,"P1") | E4: =COUNTIF('04_Notification'!U2:U75,"Not Run") | F4: =COUNTIF('04_Notification'!U2:U75,"Pass") | G4: =COUNTIF('04_Notification'!U2:U75,"Fail") | H4: =COUNTIF('04_Notification'!U2:U75,"Blocked") | I4: =IFERROR(F4/(F4+G4),0)
A5: SMTP/Security/NFR | B5: =COUNTA('05_SMTP_Sec_NFR'!B2:B19) | C5: =COUNTIF('05_SMTP_Sec_NFR'!E2:E19,"P0") | D5: =COUNTIF('05_SMTP_Sec_NFR'!E2:E19,"P1") | E5: =COUNTIF('05_SMTP_Sec_NFR'!U2:U19,"Not Run") | F5: =COUNTIF('05_SMTP_Sec_NFR'!U2:U19,"Pass") | G5: =COUNTIF('05_SMTP_Sec_NFR'!U2:U19,"Fail") | H5: =COUNTIF('05_SMTP_Sec_NFR'!U2:U19,"Blocked") | I5: =IFERROR(F5/(F5+G5),0)
A6: TỔNG | B6: =SUM(B2:B5) | C6: =SUM(C2:C5) | D6: =SUM(D2:D5) | E6: =SUM(E2:E5) | F6: =SUM(F2:F5) | G6: =SUM(G2:G5) | H6: =SUM(H2:H5) | I6: =IFERROR(F6/(F6+G6),0)

Sheet 02_Tai_khoan
A1: STT | B1: Test Case ID | C1: TraceID (Mã SRS) | D1: Nhóm/Feature | E1: Priority | F1: Type | G1: Tên Test Case / Mục tiêu | H1: Tác nhân | I1: Điểm bắt đầu luồng | J1: Pre-conditions (Tiền đề) | K1: Test Data (Dữ liệu) | L1: Các bước thực hiện | M1: Kết quả mong đợi theo bước | N1: Nguồn địa chỉ nhận | O1: Expected To / CC | P1: Mailbox KHÔNG được nhận | Q1: UI / API / Queue / SMTP / Audit cần kiểm tra | R1: Post-condition / Cleanup | S1: Kết quả thực tế | T1: Evidence | U1: Trạng thái | V1: Bug ID | W1: Tester / Ngày | X1: Ghi chú
A2: 1 | B2: EM-TK-UI-01 | C2: FR-VIII-15 / SCR-VIII-03 / srs-fr-10:676-751,1707-1743 | D2: UI field verification | E2: P0 | F2: UI | G2: Kiểm tra màn Quản lý tài khoản và form tạo/sửa | H2: QTHT | I2: Quản trị hệ thống > Tài khoản | J2: Có tài khoản đúng quyền; dữ liệu danh mục cần thiết đã seed. | K2: Không có. | L2: 1. Đăng nhập bằng đúng vai trò. 2. Mở màn hình theo điểm bắt đầu. 3. Đối chiếu từng trường, kiểu input, required/readonly và nút với SRS. 4. Kiểm tra điều kiện hiển thị/ẩn. 5. Kiểm tra tab order, label và thông báo validation khi bỏ trống. | M2: 1. Đăng nhập và phân quyền đúng. 2. Màn hình mở đúng. 3. Có đủ: danh sách đối chiếu theo SCR-VIII-03; form UI có username*, email*, họ tên*, vai trò*, đơn vị*, loại TK*, CCCD; input nghiệp vụ FR-VIII-15 còn có điện thoại; tạo mới KHÔNG có mật khẩu. 4. Nút/field chỉ hiện đúng điều kiện. 5. Required, readonly và validation đúng SRS. NEGATIVE: Không được có nút admin đặt/đổi mật khẩu; mật khẩu trên form tạo. | N2: — | O2: — | P2: — | Q2: Kiểm tra màn hình không thay đổi dữ liệu và không phát sinh email; queue/audit chỉ khi có quyền. | R2: — | S2: BUG-EM-TK-002: form sửa TK doanh nghiệp thiếu Vai trò. BA-CLAR-EM-TK-001 chờ BA chốt do FR Outputs và SCR mâu thuẫn. Evidence: bug-report/bug-report-em-tk.md | U2: Fail | V2: BUG-EM-TK-002 | W2: QA Automation / 2026-08-12 | X2: BUG-EM-TK-002: form sửa TK doanh nghiệp thiếu Vai trò. BA-CLAR-EM-TK-001 chờ BA chốt do FR Outputs và SCR mâu thuẫn. Evidence: bug-report/bug-report-em-tk.md
A3: 2 | B3: EM-TK-UI-02 | C3: FR-VIII-22 / SCR-VIII-08 / srs-fr-10:1024-1128,1900-1943 | D3: UI field verification | E3: P0 | F3: UI | G3: Kiểm tra email trên form DN tự đăng ký | H3: DN chưa có TK | I3: Đăng nhập > Đăng ký dành cho doanh nghiệp | J3: Có tài khoản đúng quyền; dữ liệu danh mục cần thiết đã seed. | K3: Không có. | L3: 1. Đăng nhập bằng đúng vai trò. 2. Mở màn hình theo điểm bắt đầu. 3. Đối chiếu từng trường, kiểu input, required/readonly và nút với SRS. 4. Kiểm tra điều kiện hiển thị/ẩn. 5. Kiểm tra tab order, label và thông báo validation khi bỏ trống. | M3: 1. Đăng nhập và phân quyền đúng. 2. Màn hình mở đúng. 3. Có đủ: một ô Email bắt buộc, tooltip nêu dùng cho login/kích hoạt/reset/notification và đồng thời là email liên hệ; username readonly tự lấy MST; mật khẩu + xác nhận + cam kết. 4. Nút/field chỉ hiện đúng điều kiện. 5. Required, readonly và validation đúng SRS. | N3: — | O3: — | P3: — | Q3: Kiểm tra màn hình không thay đổi dữ liệu và không phát sinh email; queue/audit chỉ khi có quyền. | R3: — | S3: BUG-EM-TK-003: tooltip Email doanh nghiệp thiếu mục đích login/reset mật khẩu/thông báo. Evidence: bug-report/bug-report-em-tk.md | U3: Fail | V3: BUG-EM-TK-003 | W3: QA Automation / 2026-08-12 | X3: BUG-EM-TK-003: tooltip Email doanh nghiệp thiếu mục đích login/reset mật khẩu/thông báo. Evidence: bug-report/bug-report-em-tk.md
A4: 3 | B4: EM-TK-UI-03 | C4: FR-VIII-26 / srs-fr-10:1278-1369 | D4: UI field verification | E4: P0 | F4: UI | G4: Kiểm tra form Quên mật khẩu | H4: User bất kỳ | I4: Đăng nhập > Quên mật khẩu | J4: Có tài khoản đúng quyền; dữ liệu danh mục cần thiết đã seed. | K4: Không có. | L4: 1. Đăng nhập bằng đúng vai trò. 2. Mở màn hình theo điểm bắt đầu. 3. Đối chiếu từng trường, kiểu input, required/readonly và nút với SRS. 4. Kiểm tra điều kiện hiển thị/ẩn. 5. Kiểm tra tab order, label và thông báo validation khi bỏ trống. | M4: 1. Đăng nhập và phân quyền đúng. 2. Màn hình mở đúng. 3. Có đủ: một ô Tên đăng nhập nhận email hoặc MST; nút gửi link; form qua link có mật khẩu mới + xác nhận. 4. Nút/field chỉ hiện đúng điều kiện. 5. Required, readonly và validation đúng SRS. NEGATIVE: Không được có hai ô riêng Email và MST; ô yêu cầu email khớp DOANH_NGHIEP.email. | N4: — | O4: — | P4: — | Q4: Kiểm tra màn hình không thay đổi dữ liệu và không phát sinh email; queue/audit chỉ khi có quyền. | R4: — | S4: Form yêu cầu có đúng một ô “Email hoặc Mã số thuế”, required; Gmail thật nhận thư reset tới diupt01+cb-nv-a@gmail.com, link hiệu lực 30 phút mở form có đúng “Mật khẩu mới” và “Xác nhận mật khẩu mới”. Không submit đổi mật khẩu. | U4: Pass | W4: QA Automation / 2026-08-12 | X4: Form yêu cầu có đúng một ô “Email hoặc Mã số thuế”, required; Gmail thật nhận thư reset tới diupt01+cb-nv-a@gmail.com, link hiệu lực 30 phút mở form có đúng “Mật khẩu mới” và “Xác nhận mật khẩu mới”. Không submit đổi mật khẩu.
A5: 4 | B5: EM-TK-UI-04 | C5: FR-VIII-15 / SCR-VIII-03 / srs-fr-10:1726 | D5: UI field verification | E5: P0 | F5: UI | G5: Kiểm tra điều kiện hiển thị Gửi lại email kích hoạt | H5: QTHT | I5: Quản trị hệ thống > Tài khoản | J5: Có tài khoản đúng quyền; dữ liệu danh mục cần thiết đã seed. | K5: Không có. | L5: 1. Đăng nhập bằng đúng vai trò. 2. Mở màn hình theo điểm bắt đầu. 3. Đối chiếu từng trường, kiểu input, required/readonly và nút với SRS. 4. Kiểm tra điều kiện hiển thị/ẩn. 5. Kiểm tra tab order, label và thông báo validation khi bỏ trống. | M5: 1. Đăng nhập và phân quyền đúng. 2. Màn hình mở đúng. 3. Có đủ: hành động Gửi lại email kích hoạt chỉ ở trạng thái phù hợp; không có Đổi MK. 4. Nút/field chỉ hiện đúng điều kiện. 5. Required, readonly và validation đúng SRS. | N5: — | O5: — | P5: — | Q5: Kiểm tra màn hình không thay đổi dữ liệu và không phát sinh email; queue/audit chỉ khi có quyền. | R5: — | U5: Pass | W5: QA Automation / 2026-08-12
A6: 5 | B6: EM-TK-VAL-01 | C6: FR-VIII-15 Inputs#2 | D6: Email validation | E6: P0 | F6: Negative/Edge | G6: Bỏ trống email tài khoản | H6: QTHT/CB NV/DN | I6: Quản trị > Tài khoản > Thêm mới | J6: Đang ở form có trường email; ghi nhận số bản ghi hiển thị và inbox trước test. | K6: email = rỗng | L6: 1. Mở form. 2. Nhập đầy đủ các trường khác hợp lệ. 3. Nhập email theo Test Data. 4. Bấm Lưu/Đăng ký. 5. Reload màn hình, kiểm tra UI/API response và inbox. | M6: 1-3. Form nhận đúng dữ liệu. 4. Không cho submit; field Email báo bắt buộc. 5. Reload: số bản ghi hiển thị không đổi, form không đóng/reset, không tạo token/job/email. | N6: Field email đang kiểm tra | O6: Không gửi mail nếu validation thất bại | P6: Tất cả mailbox test khi validation thất bại | Q6: Kiểm tra UI/API response, số bản ghi hiển thị và Gmail; queue/audit chỉ khi có quyền. | R6: — | S6: UI từ chối đúng, báo “Vui lòng nhập email”, giữ nguyên form và không phát sinh request submit. | U6: Pass | W6: QA Automation / 2026-08-12 | X6: UI từ chối đúng, báo “Vui lòng nhập email”, giữ nguyên form và không phát sinh request submit.
A7: 6 | B7: EM-TK-VAL-02 | C7: FR-VIII-15 Inputs#2; FR-VIII-22 Inputs#14 | D7: Email validation | E7: P0 | F7: Negative/Edge | G7: Chấp nhận email hợp lệ cơ bản | H7: QTHT/CB NV/DN | I7: Form tạo tài khoản | J7: Đang ở form có trường email; ghi nhận số bản ghi hiển thị và inbox trước test. | K7: diupt01+uat-em-tk-val-02@gmail.com | L7: 1. Mở form. 2. Nhập đầy đủ các trường khác hợp lệ. 3. Nhập email theo Test Data. 4. Bấm Lưu/Đăng ký. 5. Reload màn hình, kiểm tra UI/API response và inbox. | M7: 1-3. Form nhận đúng dữ liệu. 4. Cho lưu nếu các field khác hợp lệ. 5. Reload: email được lưu đúng; UI/API hiển thị đúng giá trị và chỉ phát sinh email nếu workflow của thao tác yêu cầu. | N7: Field email đang kiểm tra | O7: Không gửi mail nếu validation thất bại | P7: Tất cả mailbox test khi validation thất bại | Q7: Kiểm tra UI/API response, số bản ghi hiển thị và Gmail; queue/audit chỉ khi có quyền. | R7: — | S7: UI lưu thành công: POST 201, tổng tài khoản 83→84, email hiển thị đúng; Gmail thật nhận thư kích hoạt, To = diupt01+uat-em-tk-val-02@gmail.com. | U7: Pass | W7: QA Automation / 2026-08-12 | X7: UI lưu thành công: POST 201, tổng tài khoản 83→84, email hiển thị đúng; Gmail thật nhận thư kích hoạt, To = diupt01+uat-em-tk-val-02@gmail.com.
A8: 7 | B8: EM-TK-VAL-03 | C8: FR-VIII-15 Inputs#2; SCR-VIII-03 Email RFC 5322 | D8: Email validation | E8: P0 | F8: Negative/Edge | G8: Chấp nhận Gmail plus alias | H8: QTHT/CB NV/DN | I8: Form tạo tài khoản | J8: Đang ở form có trường email; ghi nhận số bản ghi hiển thị và inbox trước test. | K8: diupt01+uat-em-tk-val-03@gmail.com | L8: 1. Mở form. 2. Nhập đầy đủ các trường khác hợp lệ. 3. Nhập email theo Test Data. 4. Bấm Lưu/Đăng ký. 5. Reload màn hình, kiểm tra UI/API response và inbox. | M8: 1-3. Form nhận đúng dữ liệu. 4. Cho lưu khi các field khác hợp lệ; nếu phát sinh thư thì Gmail thật phải nhận và trường To đúng alias. 5. Reload: email được lưu đúng; UI/API hiển thị đúng giá trị và chỉ phát sinh email nếu workflow của thao tác yêu cầu. | N8: Field email đang kiểm tra | O8: Không gửi mail nếu validation thất bại | P8: Tất cả mailbox test khi validation thất bại | Q8: Kiểm tra UI/API response, số bản ghi hiển thị và Gmail; queue/audit chỉ khi có quyền. | R8: — | S8: Dấu + được chấp nhận: POST 201, tổng tài khoản 84→85; Gmail thật nhận thư kích hoạt và chi tiết To = diupt01+uat-em-tk-val-03@gmail.com. | U8: Pass | W8: QA Automation / 2026-08-12 | X8: Dấu + được chấp nhận: POST 201, tổng tài khoản 84→85; Gmail thật nhận thư kích hoạt và chi tiết To = diupt01+uat-em-tk-val-03@gmail.com.
A9: 8 | B9: EM-TK-VAL-04 | C9: FR-VIII-15 E2/format; FR-VIII-22 Inputs#14 | D9: Email validation | E9: P0 | F9: Negative/Edge | G9: Thiếu ký tự @ | H9: QTHT/CB NV/DN | I9: Form tạo tài khoản | J9: Đang ở form có trường email; ghi nhận số bản ghi hiển thị và inbox trước test. | K9: email = qa.example.test | L9: 1. Mở form. 2. Nhập đầy đủ các trường khác hợp lệ. 3. Nhập email theo Test Data. 4. Bấm Lưu/Đăng ký. 5. Reload màn hình, kiểm tra UI/API response và inbox. | M9: 1-3. Form nhận đúng dữ liệu. 4. Từ chối, hiển thị lỗi định dạng email; không lưu. 5. Reload: số bản ghi hiển thị không đổi, form không đóng/reset, không tạo token/job/email. | N9: Field email đang kiểm tra | O9: Không gửi mail nếu validation thất bại | P9: Tất cả mailbox test khi validation thất bại | Q9: Kiểm tra UI/API response, số bản ghi hiển thị và Gmail; queue/audit chỉ khi có quyền. | R9: — | S9: UI từ chối đúng, báo “Email không hợp lệ”, giữ form và tổng tài khoản vẫn 85; không phát sinh request submit. | U9: Pass | W9: QA Automation / 2026-08-12 | X9: UI từ chối đúng, báo “Email không hợp lệ”, giữ form và tổng tài khoản vẫn 85; không phát sinh request submit.
A10: 9 | B10: EM-TK-VAL-05 | C10: FR-VIII-15 E2/format; FR-VIII-22 Inputs#14 | D10: Email validation | E10: P0 | F10: Negative/Edge | G10: Thiếu local-part | H10: QTHT/CB NV/DN | I10: Form tạo tài khoản | J10: Đang ở form có trường email; ghi nhận số bản ghi hiển thị và inbox trước test. | K10: email = @example.test | L10: 1. Mở form. 2. Nhập đầy đủ các trường khác hợp lệ. 3. Nhập email theo Test Data. 4. Bấm Lưu/Đăng ký. 5. Reload màn hình, kiểm tra UI/API response và inbox. | M10: 1-3. Form nhận đúng dữ liệu. 4. Từ chối, hiển thị lỗi định dạng email; không lưu. 5. Reload: số bản ghi hiển thị không đổi, form không đóng/reset, không tạo token/job/email. | N10: Field email đang kiểm tra | O10: Không gửi mail nếu validation thất bại | P10: Tất cả mailbox test khi validation thất bại | Q10: Kiểm tra UI/API response, số bản ghi hiển thị và Gmail; queue/audit chỉ khi có quyền. | R10: — | S10: UI từ chối đúng chuỗi @example.test, báo “Email không hợp lệ”, giữ nguyên form; tổng tài khoản không đổi ở 86 và không phát sinh request submit. | U10: Pass | W10: QA Automation / 2026-08-12 | X10: UI từ chối đúng chuỗi @example.test, báo “Email không hợp lệ”, giữ nguyên form; tổng tài khoản không đổi ở 86 và không phát sinh request submit.
A11: 10 | B11: EM-TK-VAL-06 | C11: FR-VIII-15 E2/format; FR-VIII-22 Inputs#14 | D11: Email validation | E11: P0 | F11: Negative/Edge | G11: Thiếu domain | H11: QTHT/CB NV/DN | I11: Form tạo tài khoản | J11: Đang ở form có trường email; ghi nhận số bản ghi hiển thị và inbox trước test. | K11: email = qa@ | L11: 1. Mở form. 2. Nhập đầy đủ các trường khác hợp lệ. 3. Nhập email theo Test Data. 4. Bấm Lưu/Đăng ký. 5. Reload màn hình, kiểm tra UI/API response và inbox. | M11: 1-3. Form nhận đúng dữ liệu. 4. Từ chối, hiển thị lỗi định dạng email; không lưu. 5. Reload: số bản ghi hiển thị không đổi, form không đóng/reset, không tạo token/job/email. | N11: Field email đang kiểm tra | O11: Không gửi mail nếu validation thất bại | P11: Tất cả mailbox test khi validation thất bại | Q11: Kiểm tra UI/API response, số bản ghi hiển thị và Gmail; queue/audit chỉ khi có quyền. | R11: — | S11: UI từ chối đúng chuỗi qa@, báo “Email không hợp lệ”, giữ nguyên form; tổng tài khoản không đổi ở 86 và không phát sinh request submit. | U11: Pass | W11: QA Automation / 2026-08-12 | X11: UI từ chối đúng chuỗi qa@, báo “Email không hợp lệ”, giữ nguyên form; tổng tài khoản không đổi ở 86 và không phát sinh request submit.
A12: 11 | B12: EM-TK-VAL-07 | C12: FR-VIII-15 E2/format; FR-VIII-22 Inputs#14 | D12: Email validation | E12: P0 | F12: Negative/Edge | G12: Có khoảng trắng giữa | H12: QTHT/CB NV/DN | I12: Form tạo tài khoản | J12: Đang ở form có trường email; ghi nhận số bản ghi hiển thị và inbox trước test. | K12: email = qa user@example.test | L12: 1. Mở form. 2. Nhập đầy đủ các trường khác hợp lệ. 3. Nhập email theo Test Data. 4. Bấm Lưu/Đăng ký. 5. Reload màn hình, kiểm tra UI/API response và inbox. | M12: 1-3. Form nhận đúng dữ liệu. 4. Từ chối, hiển thị lỗi định dạng email; không lưu. 5. Reload: số bản ghi hiển thị không đổi, form không đóng/reset, không tạo token/job/email. | N12: Field email đang kiểm tra | O12: Không gửi mail nếu validation thất bại | P12: Tất cả mailbox test khi validation thất bại | Q12: Kiểm tra UI/API response, số bản ghi hiển thị và Gmail; queue/audit chỉ khi có quyền. | R12: — | S12: UI giữ nguyên đúng chuỗi có khoảng trắng, báo “Email không hợp lệ”, giữ form; tổng tài khoản không đổi ở 86 và không phát sinh request submit. | U12: Pass | W12: QA Automation / 2026-08-12 | X12: UI giữ nguyên đúng chuỗi có khoảng trắng, báo “Email không hợp lệ”, giữ form; tổng tài khoản không đổi ở 86 và không phát sinh request submit.
A13: 12 | B13: EM-TK-VAL-08 | C13: FR-VIII-15 E2/format; FR-VIII-22 Inputs#14 | D13: Email validation | E13: P0 | F13: Negative/Edge | G13: Domain có hai dấu chấm liên tiếp | H13: QTHT/CB NV/DN | I13: Form tạo tài khoản | J13: Đang ở form có trường email; ghi nhận số bản ghi hiển thị và inbox trước test. | K13: email = qa@example..test | L13: 1. Mở form. 2. Nhập đầy đủ các trường khác hợp lệ. 3. Nhập email theo Test Data. 4. Bấm Lưu/Đăng ký. 5. Reload màn hình, kiểm tra UI/API response và inbox. | M13: 1-3. Form nhận đúng dữ liệu. 4. Từ chối, hiển thị lỗi định dạng email; không lưu. 5. Reload: số bản ghi hiển thị không đổi, form không đóng/reset, không tạo token/job/email. | N13: Field email đang kiểm tra | O13: Không gửi mail nếu validation thất bại | P13: Tất cả mailbox test khi validation thất bại | Q13: Kiểm tra UI/API response, số bản ghi hiển thị và Gmail; queue/audit chỉ khi có quyền. | R13: — | S13: UI giữ nguyên chuỗi qa@example..test, báo “Email không hợp lệ”, giữ form; tổng tài khoản không đổi ở 86 và không phát sinh request submit. | U13: Pass | W13: QA Automation / 2026-08-12 | X13: UI giữ nguyên chuỗi qa@example..test, báo “Email không hợp lệ”, giữ form; tổng tài khoản không đổi ở 86 và không phát sinh request submit.
A14: 13 | B14: EM-TK-VAL-09 | C14: TAI_KHOAN.email UNIQUE; FR-VIII-15 E2 ERR-TK-02 / srs-fr-10:737 | D14: Email validation | E14: P0 | F14: Negative/Edge | G14: Email trùng tài khoản cùng vai trò | H14: QTHT/CB NV/DN | I14: Quản trị > Tài khoản > Thêm mới | J14: Đang ở form có trường email; ghi nhận số bản ghi hiển thị và inbox trước test. | K14: Email đã thuộc CB_A | L14: 1. Mở form. 2. Nhập đầy đủ các trường khác hợp lệ. 3. Nhập email theo Test Data. 4. Bấm Lưu/Đăng ký. 5. Reload màn hình, kiểm tra UI/API response và inbox. | M14: 1-3. Form nhận đúng dữ liệu. 4. Từ chối với ERR-TK-02: "Email '{email}' đã được sử dụng". 5. Reload: số bản ghi hiển thị không đổi, form không đóng/reset, không tạo token/job/email. | N14: Field email đang kiểm tra | O14: Không gửi mail nếu validation thất bại | P14: Tất cả mailbox test khi validation thất bại | Q14: Kiểm tra UI/API response, số bản ghi hiển thị và Gmail; queue/audit chỉ khi có quyền. | R14: — | S14: BUG-EM-TK-004: POST 409 trả ERR-VAL-VIII-113-02/“Email đã tồn tại trong hệ thống” thay vì ERR-TK-02/“Email '{email}' đã được sử dụng”; UI không hiển thị lỗi. Evidence: bug-report/bug-report-em-tk.md | U14: Fail | V14: BUG-EM-TK-004 | W14: QA Automation / 2026-08-12 | X14: BUG-EM-TK-004: POST 409 trả ERR-VAL-VIII-113-02/“Email đã tồn tại trong hệ thống” thay vì ERR-TK-02/“Email '{email}' đã được sử dụng”; UI không hiển thị lỗi. Evidence: bug-report/bug-report-em-tk.md
A15: 14 | B15: EM-TK-VAL-10 | C15: TAI_KHOAN.email UNIQUE; FR-VIII-22 E3 ERR-REG-02 | D15: Email validation | E15: P0 | F15: Negative/Edge | G15: Email trùng tài khoản khác vai trò | H15: QTHT/CB NV/DN | I15: Đăng ký DN | J15: Đang ở form có trường email; ghi nhận số bản ghi hiển thị và inbox trước test. | K15: Email đã thuộc TVV nhưng MST DN mới | L15: 1. Mở form. 2. Nhập đầy đủ các trường khác hợp lệ. 3. Nhập email theo Test Data. 4. Bấm Lưu/Đăng ký. 5. Reload màn hình, kiểm tra UI/API response và inbox. | M15: 1-3. Form nhận đúng dữ liệu. 4. Từ chối với ERR-REG-02: "Email đã được sử dụng". 5. Reload: số bản ghi hiển thị không đổi, form không đóng/reset, không tạo token/job/email. | N15: Field email đang kiểm tra | O15: Không gửi mail nếu validation thất bại | P15: Tất cả mailbox test khi validation thất bại | Q15: Kiểm tra UI/API response, số bản ghi hiển thị và Gmail; queue/audit chỉ khi có quyền. | R15: — | S15: DN dùng MST mới 0312082697 và email của TVV: POST trả 409 ERR-REG-02, UI hiển thị đúng “Email đã được sử dụng”, form giữ nguyên; Gmail thật không có thư mới tới alias trong 1 giờ gần nhất. | U15: Pass | W15: QA Automation / 2026-08-12 | X15: DN dùng MST mới 0312082697 và email của TVV: POST trả 409 ERR-REG-02, UI hiển thị đúng “Email đã được sử dụng”, form giữ nguyên; Gmail thật không có thư mới tới alias trong 1 giờ gần nhất.
A16: 15 | B16: EM-TK-VAL-13 | C16: [NGOÀI SRS] §3.5 Security; email header injection | D16: Email validation | E16: P0 | F16: Negative/Edge | G16: Chống chèn header email | H16: QTHT/CB NV/DN | I16: Form tạo tài khoản | J16: Đang ở form có trường email; ghi nhận số bản ghi hiển thị và inbox trước test. | K16: diupt01+uat-em-tk-val-13@gmail.com\r\nBcc:diupt01+attacker@gmail.com | L16: 1. Mở form. 2. Nhập đầy đủ các trường khác hợp lệ. 3. Nhập email theo Test Data. 4. Bấm Lưu/Đăng ký. 5. Reload màn hình, kiểm tra UI/API response và inbox. | M16: 1-3. Form nhận đúng dữ liệu. 4. Từ chối dữ liệu; tuyệt đối không sinh thư tới MB_ATTACKER. 5. Reload: số bản ghi hiển thị không đổi, form không đóng/reset, không tạo token/job/email. | N16: Field email đang kiểm tra | O16: Không gửi mail nếu validation thất bại | P16: Tất cả mailbox test khi validation thất bại | Q16: Kiểm tra UI/API response, số bản ghi hiển thị và Gmail; queue/audit chỉ khi có quyền. | R16: — | S16: [Ngoài SRS] Chrome loại CR/LF khỏi input; chuỗi còn lại bị từ chối với “Email không hợp lệ”, form và tổng 86 giữ nguyên, không phát sinh request submit. Gmail thật không có thư mới tới diupt01+uat-em-tk-val-13@gmail.com hoặc diupt01+attacker@gmail.com trong 1 giờ gần nhất. | U16: Pass | W16: QA Automation / 2026-08-12 | X16: [Ngoài SRS] Chrome loại CR/LF khỏi input; chuỗi còn lại bị từ chối với “Email không hợp lệ”, form và tổng 86 giữ nguyên, không phát sinh request submit. Gmail thật không có thư mới tới diupt01+uat-em-tk-val-13@gmail.com hoặc diupt01+attacker@gmail.com trong 1 giờ gần nhất.
A17: 16 | B17: EM-TK-ACT-01 | C17: FR-VIII-15 / SM-TAIKHOAN | D17: Cấp/kích hoạt tài khoản | E17: P0 | F17: Workflow | G17: QTHT tạo tài khoản cán bộ và gửi mail kích hoạt | H17: QTHT | I17: Quản trị > Tài khoản > Thêm mới | J17: Username/email mới; đơn vị và vai trò tồn tại. | K17: cb_email_01 / diupt01+uat-em-tk-act-01@gmail.com | L17: 1. Dọn inbox; ghi count TAI_KHOAN/queue. 2. Điền form, không có field mật khẩu. 3. Bấm Lưu một lần. 4. Mở inbox email mới. 5. Kiểm tra UI/API/role/audit. | M17: 1. Baseline sạch. 2. Form hợp lệ, admin không biết/đặt mật khẩu. 3. Tạo 1 TAI_KHOAN trạng thái CHO_KICH_HOAT và gán sẵn role/đơn vị. 4. Nhận đúng 1 email có link đặt mật khẩu lần đầu. 5. Có token/audit; chưa đăng nhập được trước kích hoạt. | N17: TAI_KHOAN.email | O17: To: diupt01+uat-em-tk-act-01@gmail.com | P17: Mailbox khác vai trò; email cũ | Q17: Kiểm tra TAI_KHOAN.trang_thai, role/link entity, token, email queue/SMTP message-id, AUDIT_LOG; chỉ một thư. | R17: Dùng fixture riêng; sau test khóa/vô hiệu hóa account nếu cần. | U17: Not Run
A18: 17 | B18: EM-TK-ACT-02 | C18: FR-IV-07 / FR-VIII-15 / srs-fr-04:598-636 | D18: Cấp/kích hoạt tài khoản | E18: P0 | F18: Workflow | G18: Duyệt TVV tự cấp TK và gửi mail kích hoạt | H18: CB Phê duyệt cùng đơn vị | I18: Hồ sơ TVV > Phê duyệt | J18: TVV ở CHO_PHE_DUYET, email mới, hồ sơ hợp lệ. | K18: diupt01+uat-em-tk-act-02@gmail.com; số quyết định hợp lệ | L18: 1. Dọn inbox/ghi baseline. 2. Mở hồ sơ TVV chờ duyệt. 3. Nhập số quyết định và phê duyệt. 4. Kiểm tra inbox TVV. 5. Kiểm tra TVV, TK, role, link và audit. | M18: 1. Baseline sạch. 2. Đúng hồ sơ/quyền. 3. TVV và TK chuyển CHO_KICH_HOAT; tạo username từ local-part, role TVV/CG và đơn vị. 4. Đúng 1 mail kích hoạt có mã số TVV/link. 5. Liên kết 1:1 và audit đúng. | N18: TU_VAN_VIEN.email được copy sang TAI_KHOAN.email | O18: To: diupt01+uat-em-tk-act-02@gmail.com | P18: Mailbox khác vai trò; email cũ | Q18: Kiểm tra TAI_KHOAN.trang_thai, role/link entity, token, email queue/SMTP message-id, AUDIT_LOG; chỉ một thư. | R18: Dùng fixture riêng; sau test khóa/vô hiệu hóa account nếu cần. | U18: Not Run
A19: 18 | B19: EM-TK-ACT-03 | C19: FR-IV-NHT-01 / srs-fr-04:1214-1266 | D19: Cấp/kích hoạt tài khoản | E19: P0 | F19: Workflow | G19: Tạo NHT gửi mail kích hoạt | H19: QTHT/CB NV đúng đơn vị | I19: Quản lý Người hỗ trợ > Thêm mới | J19: Email/username mới; đơn vị và ≥1 lĩnh vực hợp lệ. | K19: diupt01+uat-em-tk-act-03@gmail.com | L19: 1. Dọn inbox/ghi baseline. 2. Điền đủ form NHT. 3. Lưu. 4. Kiểm tra inbox. 5. Kiểm tra NGUOI_HO_TRO, TAI_KHOAN, role và audit. | M19: 1-2. Dữ liệu hợp lệ. 3. Tạo đúng 1 NHT + 1 TK ở CHO_KICH_HOAT, gán role NHT. 4. Nhận đúng 1 mail link đặt mật khẩu lần đầu. 5. Entity liên kết, đơn vị/lĩnh vực đúng. | N19: NGUOI_HO_TRO/TAI_KHOAN.email | O19: To: diupt01+uat-em-tk-act-03@gmail.com | P19: Mailbox khác vai trò; email cũ | Q19: Kiểm tra TAI_KHOAN.trang_thai, role/link entity, token, email queue/SMTP message-id, AUDIT_LOG; chỉ một thư. | R19: Dùng fixture riêng; sau test khóa/vô hiệu hóa account nếu cần. | U19: Not Run
A20: 19 | B20: EM-TK-ACT-04 | C20: FR-VIII-22 Processing#10,#12 | D20: Cấp/kích hoạt tài khoản | E20: P0 | F20: Workflow | G20: DN tự đăng ký nhận link chỉ kích hoạt | H20: DN chưa có TK | I20: Đăng nhập > Đăng ký DN | J20: MST/email mới; toàn bộ field bắt buộc hợp lệ. | K20: MST 0100000001; diupt01+uat-em-tk-act-04@gmail.com; mật khẩu Test@12345 | L20: 1. Dọn inbox/ghi baseline. 2. Điền form và mật khẩu. 3. Đăng ký. 4. Mở email và bấm link. 5. Quan sát trang sau link; đăng nhập bằng MST và mật khẩu đã đăng ký. | M20: 1. Baseline sạch. 2. Form hợp lệ. 3. TK CHO_KICH_HOAT + DN được tạo, role DN gán sẵn. 4. Link hợp lệ chuyển TK HOAT_DONG và bị hủy. 5. Link KHÔNG hỏi đặt lại mật khẩu; đăng nhập bằng mật khẩu ban đầu thành công. | N20: TAI_KHOAN.email | O20: To: diupt01+uat-em-tk-act-04@gmail.com | P20: Mailbox khác vai trò; email cũ | Q20: Kiểm tra TAI_KHOAN.trang_thai, role/link entity, token, email queue/SMTP message-id, AUDIT_LOG; chỉ một thư. | R20: Dùng fixture riêng; sau test khóa/vô hiệu hóa account nếu cần. | U20: Not Run
A21: 20 | B21: EM-TK-ACT-05 | C21: FR-VIII-26 Processing#7-14 | D21: Cấp/kích hoạt tài khoản | E21: P0 | F21: Workflow | G21: TVV/NHT/CB kích hoạt lần đầu kèm đặt mật khẩu | H21: TVV/NHT/CB | I21: Link kích hoạt trong email | J21: TK CHO_KICH_HOAT chưa có mật khẩu; token hợp lệ chưa dùng. | K21: Mật khẩu mới Test@12345 | L21: 1. Bấm link trong mail. 2. Kiểm tra form đặt mật khẩu. 3. Nhập mật khẩu + xác nhận. 4. Submit. 5. Đăng nhập và kiểm tra entity liên quan. | M21: 1. Link mở được. 2. Có 2 field mật khẩu, không yêu cầu lại email. 3-4. Mật khẩu đủ mạnh được hash; token bị hủy; TK HOAT_DONG. 5. Đăng nhập được; TVV/NHT liên quan đồng thời HOAT_DONG. | N21: Link đã gửi tới TAI_KHOAN.email | O21: Không phát sinh email mới | P21: Mailbox khác vai trò; email cũ | Q21: Kiểm tra TAI_KHOAN.trang_thai, role/link entity, token, email queue/SMTP message-id, AUDIT_LOG; chỉ một thư. | R21: Dùng fixture riêng; sau test khóa/vô hiệu hóa account nếu cần. | U21: Not Run
A22: 21 | B22: EM-TK-ACT-06 | C22: FR-VIII-22 E8 ERR-REG-ACT-01 | D22: Cấp/kích hoạt tài khoản | E22: P0 | F22: Workflow | G22: Link kích hoạt DN sai/không tồn tại | H22: User nhận mail | I22: URL token | J22: Có fixture đúng loại token. | K22: token sửa 1 ký tự | L22: 1. Ghi trạng thái/mật khẩu hash hiện tại. 2. Mở URL chứa token theo Test Data. 3. Thử submit nếu form xuất hiện. 4. Kiểm tra UI và UI/API. | M22: 1. Có baseline. 2-3. Hiển thị nguyên văn: 'Liên kết kích hoạt không hợp lệ. Vui lòng kiểm tra lại thư điện tử hoặc liên hệ hỗ trợ.'; không đổi trạng thái. 4. Không tạo session/token mới, không có audit kích hoạt thành công giả. | N22: Không áp dụng | O22: Không phát sinh mail | P22: Mailbox khác vai trò; email cũ | Q22: Kiểm tra TAI_KHOAN.trang_thai, role/link entity, token, email queue/SMTP message-id, AUDIT_LOG; chỉ một thư. | R22: Dùng fixture riêng; sau test khóa/vô hiệu hóa account nếu cần. | U22: Not Run
A23: 22 | B23: EM-TK-ACT-07 | C23: FR-VIII-22 E9 ERR-REG-ACT-02 | D23: Cấp/kích hoạt tài khoản | E23: P0 | F23: Workflow | G23: Dùng lại link kích hoạt DN | H23: User nhận mail | I23: URL token | J23: Có fixture đúng loại token. | K23: token đã dùng | L23: 1. Ghi trạng thái/mật khẩu hash hiện tại. 2. Mở URL chứa token theo Test Data. 3. Thử submit nếu form xuất hiện. 4. Kiểm tra UI và UI/API. | M23: 1. Có baseline. 2-3. Hiển thị nguyên văn: 'Liên kết kích hoạt đã được sử dụng. Tài khoản của bạn có thể đã kích hoạt — vui lòng đăng nhập.'; không thực hiện lần hai. 4. Không tạo session/token mới, không có audit kích hoạt thành công giả. | N23: Không áp dụng | O23: Không phát sinh mail | P23: Mailbox khác vai trò; email cũ | Q23: Kiểm tra TAI_KHOAN.trang_thai, role/link entity, token, email queue/SMTP message-id, AUDIT_LOG; chỉ một thư. | R23: Dùng fixture riêng; sau test khóa/vô hiệu hóa account nếu cần. | U23: Not Run
A24: 23 | B24: EM-TK-ACT-08 | C24: FR-VIII-26 E4 ERR-PWD-04 | D24: Cấp/kích hoạt tài khoản | E24: P0 | F24: Workflow | G24: Dùng lại link đặt mật khẩu lần đầu | H24: User nhận mail | I24: URL token | J24: Có fixture đúng loại token. | K24: reset token đã dùng | L24: 1. Ghi trạng thái/mật khẩu hash hiện tại. 2. Mở URL chứa token theo Test Data. 3. Thử submit nếu form xuất hiện. 4. Kiểm tra UI và UI/API. | M24: 1. Có baseline. 2-3. Hiển thị 'Link đặt mật khẩu đã được sử dụng. Vui lòng yêu cầu link mới'; mật khẩu/trạng thái không đổi. 4. Không tạo session/token mới, không có audit kích hoạt thành công giả. | N24: Không áp dụng | O24: Không phát sinh mail | P24: Mailbox khác vai trò; email cũ | Q24: Kiểm tra TAI_KHOAN.trang_thai, role/link entity, token, email queue/SMTP message-id, AUDIT_LOG; chỉ một thư. | R24: Dùng fixture riêng; sau test khóa/vô hiệu hóa account nếu cần. | U24: Not Run
A25: 24 | B25: EM-TK-ACT-09 | C25: SCR-VIII-03 srs-fr-10:1726 / FR-VIII-26 Processing#5 srs-fr-10:1322 / FR-VIII-22 token 1 lần srs-fr-10:1088 / TAI_KHOAN.token_reset_mk srs-v3.5:2121,2127 / BR-DATA-05 | D25: Cấp/kích hoạt tài khoản | E25: P0 | F25: Workflow | G25: Gửi lại email kích hoạt và kiểm link một lần dùng | H25: QTHT | I25: Quản trị > Tài khoản > CHO_KICH_HOAT | J25: TK CHO_KICH_HOAT đã có token/link cũ. | K25: Mailbox account; lưu URL cũ | L25: 1. Lưu token/link cũ. 2. Bấm Gửi lại email kích hoạt một lần. 3. Nhận email mới và so sánh URL với link cũ. 4. Mở link trong email mới để kích hoạt/đặt mật khẩu. 5. Dùng lại chính link vừa dùng và kiểm tra UI/API. | M25: 1. Có baseline. 2-3. Nhận được thư kích hoạt. URL trong thư gửi lại trùng với link cũ là hành vi hợp lệ theo SRS hiện tại — ghi Actual link trùng hay khác, không Fail. [NGOÀI SRS] Số lượng thư, UI message, rate-limit và việc reuse hay thay token cũ chỉ ghi observation/BA clarification. 4. Link trong thư thực hiện đúng luồng kích hoạt. 5. Dùng lại cùng link bị từ chối vì token chỉ dùng một lần; hệ thống ghi nhật ký thao tác theo BR-DATA-05. | N25: TAI_KHOAN.email | O25: To: email TK | P25: Mailbox khác vai trò; email cũ | Q25: UI/API và Gmail; link trong thư hoạt động đúng luồng và bị từ chối khi dùng lại; audit thao tác nếu có quyền. Không bắt token mới khác token cũ, mã audit cụ thể hoặc số lượng thư vì SRS không đặc tả. | R25: Dùng fixture riêng; sau test khóa/vô hiệu hóa account nếu cần. | U25: Not Run
A26: 25 | B26: EM-TK-ACT-10 | C26: BR-DATA/Concurrency; FR-VIII-15 | D26: Cấp/kích hoạt tài khoản | E26: P0 | F26: Workflow | G26: Double-click tạo tài khoản không tạo trùng/email trùng | H26: QTHT | I26: Form Thêm tài khoản | J26: Email/username mới; có thể gửi hai request gần đồng thời. | K26: diupt01+uat-em-tk-act-10@gmail.com | L26: 1. Dọn inbox/ghi baseline. 2. Điền form hợp lệ. 3. Double-click Lưu hoặc gửi 2 request đồng thời. 4. Chờ queue. 5. Kiểm tra UI/API/inbox/audit. | M26: 1-2. Baseline/dữ liệu đúng. 3. Hệ thống xử lý idempotent/unique. 4-5. Chỉ 1 TK, 1 token hiệu lực, 1 email kích hoạt; request còn lại bị chặn, không 500/duplicate. | N26: TAI_KHOAN.email | O26: To: diupt01+uat-em-tk-act-10@gmail.com | P26: Mailbox khác vai trò; email cũ | Q26: Kiểm tra TAI_KHOAN.trang_thai, role/link entity, token, email queue/SMTP message-id, AUDIT_LOG; chỉ một thư. | R26: Dùng fixture riêng; sau test khóa/vô hiệu hóa account nếu cần. | U26: Not Run
A27: 26 | B27: EM-TK-ACT-11 | C27: FR-IV-07 W1 WRN-PD-01 / srs-fr-04:622-634 | D27: Cấp/kích hoạt tài khoản | E27: P0 | F27: Workflow | G27: SMTP lỗi khi duyệt TVV không rollback phê duyệt | H27: CB Phê duyệt | I27: Hồ sơ TVV > Phê duyệt | J27: SMTP giả lập lỗi; TVV CHO_PHE_DUYET hợp lệ. | K27: tvv.smtp.fail@example.invalid | L27: 1. Cấu hình SMTP stub trả lỗi. 2. Phê duyệt TVV. 3. Quan sát UI. 4. Kiểm tra TVV/TK. 5. Kiểm tra queue/log/audit. | M27: 1. Fault injection hoạt động. 2. Quyết định duyệt vẫn commit. 3. Hiển thị WRN-PD-01 nguyên văn theo SRS. 4. TVV và TK vẫn CHO_KICH_HOAT. 5. Mail ghi thất bại/retry; không tạo rollback hoặc TK thứ hai. | N27: TAI_KHOAN.email | O27: Không có SMTP accepted | P27: Mọi mailbox | Q27: TVV/TK CHO_KICH_HOAT; warning WRN-PD-01; failure log; retry; audit APPROVE vẫn tồn tại. | R27: Dùng fixture riêng; sau test khóa/vô hiệu hóa account nếu cần. | U27: Not Run
A28: 27 | B28: EM-TK-ACT-12 | C28: SM-TVV CHO_KICH_HOAT→VO_HIEU_HOA / srs-fr-04:1597 | D28: Cấp/kích hoạt tài khoản | E28: P0 | F28: Workflow | G28: Vô hiệu hóa TVV làm link kích hoạt cũ vô tác dụng | H28: CB NV | I28: Chi tiết TVV CHO_KICH_HOAT > Cập nhật trạng thái | J28: TVV/TK CHO_KICH_HOAT; đã có link kích hoạt; lý do ≥10 ký tự. | K28: Lý do: Email nhập sai, không liên lạc được TVV | L28: 1. Lưu link kích hoạt. 2. Vô hiệu hóa khẩn cấp với lý do hợp lệ. 3. Mở lại link cũ. 4. Kiểm tra TVV/TK/audit. | M28: 1. Có token cũ. 2. TVV/TK bị vô hiệu hóa, token invalidated. 3. Link cũ không thể kích hoạt/đặt mật khẩu. 4. Audit đủ người, thời gian, lý do; thông báo CB PD theo SRS. | N28: Không áp dụng | O28: Thông báo CB PD nếu email channel áp dụng | P28: Mailbox khác vai trò; email cũ | Q28: Kiểm tra TAI_KHOAN.trang_thai, role/link entity, token, email queue/SMTP message-id, AUDIT_LOG; chỉ một thư. | R28: Dùng fixture riêng; sau test khóa/vô hiệu hóa account nếu cần. | U28: Not Run
... A45: 44 | B45: EM-TK-CHG-06 | C45: FR-VIII-15 / SCR-VIII-03 / BR-AUTH-EMAIL-01 / FR-VIII-28 / SCR-VIII-10 srs-fr-10:1370-1428,1969-1990 | D45: Đổi email tài khoản | E45: P1 | F45: Workflow/Negative | G45: Audit thay đổi email tài khoản | H45: QTHT | I45: Quản trị hệ thống > Tài khoản > Sửa | J45: Có TK và dữ liệu theo Test Data. | K45: old/new | L45: 1. QTHT mở form Sửa tài khoản. 2. Ghi email TK và DN trước test. 3. Sửa Email theo Test Data và lưu. 4. Reload và phát sinh notification/reset nếu case yêu cầu. 5. Kiểm tra UI/API/inbox; với CHG-06 mở Nhật ký hệ thống, lọc thao tác Sửa của đúng QTHT/entity rồi expand Chi tiết thay đổi. | M45: 1. Form Sửa có trường Email theo SCR-VIII-03. 2-5. Nhật ký hiển thị đúng actor, thời gian, entity/mã bản ghi, loại Sửa và JSON diff email old→new; read-only. | N45: TAI_KHOAN.email | O45: Email mới khi action thành công | P45: Email cũ và DOANH_NGHIEP.email trừ khi trùng giá trị | Q45: UI/API; TAI_KHOAN.email; DOANH_NGHIEP.email; Gmail; CHG-06 kiểm trên màn Nhật ký hệ thống. | R45: — | U45: Not Run
A46: 45 | B46: EM-TK-2FA-01 | C46: BR-AUTH-01 canonical srs-v3.5:5582,5596 vs FR-VIII-20 srs-fr-10:901-974 | D46: Đăng nhập 2FA | E46: P0 | F46: Security | G46: Bắt buộc yếu tố thứ hai sau username/password đúng | H46: Cán bộ nội bộ | I46: Màn đăng nhập Tier 1 | J46: Tài khoản nội bộ HOAT_DONG; username/password đúng. | K46: CB nội bộ HOAT_DONG | L46: 1. Dọn mailbox/chuẩn bị authenticator. 2. Nhập username/password đúng. 3. Quan sát nguồn nhận mã. 4. Nhập mã theo Test Data. 5. Kiểm tra session, login audit và mailbox. | M46: 1-2. Qua bước mật khẩu. 3. Hệ thống PHẢI yêu cầu yếu tố thứ hai trước khi cấp session/JWT; đăng nhập thẳng sau bước mật khẩu là Fail. Ghi kênh nhận mã thực tế làm bằng chứng nhưng không chấm đúng/sai kênh — chờ BA tại GAP-EMAIL-01. 4-5. Ghi Actual, kênh triển khai và bằng chứng session/mailbox theo phạm vi case. | N46: Kênh triển khai thực tế; chờ BA chốt email hay authenticator | O46: Ghi Actual | P46: User khác | Q46: Session/JWT chỉ sinh sau 2FA; LOGIN audit; OTP/token không lộ log. | R46: — | U46: Not Run | X46: BR-AUTH-01 canonical yêu cầu email nhưng FR-VIII-20 vẫn ghi ứng dụng xác thực; build thiếu hoàn toàn yếu tố thứ hai là Fail nếu chưa có BA de-scope bằng văn bản.
A47: 46 | B47: EM-TK-2FA-02 | C47: BR-AUTH-01 canonical srs-v3.5:5582,5596 vs FR-VIII-20 srs-fr-10:901-974 | D47: Đăng nhập 2FA | E47: P0 | F47: Security | G47: Mã 2FA đúng | H47: Cán bộ nội bộ | I47: Màn đăng nhập Tier 1 | J47: Tài khoản nội bộ HOAT_DONG; username/password đúng. | K47: Mã 6 số hợp lệ | L47: 1. Dọn mailbox/chuẩn bị authenticator. 2. Nhập username/password đúng. 3. Quan sát nguồn nhận mã. 4. Nhập mã theo Test Data. 5. Kiểm tra session, login audit và mailbox. | M47: 1-2. Qua bước mật khẩu. 3. Chỉ tạo session khi mã đúng và còn hạn. 4-5. Với case 02-04 chỉ chấm hành vi mã/session, không chấm kênh nhận mã; ghi bằng chứng kênh triển khai thực tế. | N47: Kênh triển khai thực tế; chờ BA chốt email hay authenticator | O47: Ghi Actual | P47: User khác | Q47: Session/JWT chỉ sinh sau 2FA; LOGIN audit; OTP/token không lộ log. | R47: — | U47: Not Run | X47: BR-AUTH-01 canonical yêu cầu email nhưng FR-VIII-20 vẫn ghi ứng dụng xác thực; build thiếu hoàn toàn yếu tố thứ hai là Fail nếu chưa có BA de-scope bằng văn bản.
A48: 47 | B48: EM-TK-2FA-03 | C48: BR-AUTH-01 canonical srs-v3.5:5582,5596 vs FR-VIII-20 srs-fr-10:901-974 | D48: Đăng nhập 2FA | E48: P0 | F48: Security | G48: Mã 2FA sai | H48: Cán bộ nội bộ | I48: Màn đăng nhập Tier 1 | J48: Tài khoản nội bộ HOAT_DONG; username/password đúng. | K48: 000000 | L48: 1. Dọn mailbox/chuẩn bị authenticator. 2. Nhập username/password đúng. 3. Quan sát nguồn nhận mã. 4. Nhập mã theo Test Data. 5. Kiểm tra session, login audit và mailbox. | M48: 1-2. Qua bước mật khẩu. 3. ERR-DN-08; không tạo session. 4-5. Với case 02-04 chỉ chấm hành vi mã/session, không chấm kênh nhận mã; ghi bằng chứng kênh triển khai thực tế. | N48: Kênh triển khai thực tế; chờ BA chốt email hay authenticator | O48: Ghi Actual | P48: User khác | Q48: Session/JWT chỉ sinh sau 2FA; LOGIN audit; OTP/token không lộ log. | R48: — | U48: Not Run | X48: BR-AUTH-01 canonical yêu cầu email nhưng FR-VIII-20 vẫn ghi ứng dụng xác thực; build thiếu hoàn toàn yếu tố thứ hai là Fail nếu chưa có BA de-scope bằng văn bản.
A49: 48 | B49: EM-TK-2FA-04 | C49: BR-AUTH-01 canonical srs-v3.5:5582,5596 vs FR-VIII-20 srs-fr-10:901-974 | D49: Đăng nhập 2FA | E49: P0 | F49: Security | G49: Mã 2FA hết hạn | H49: Cán bộ nội bộ | I49: Màn đăng nhập Tier 1 | J49: Tài khoản nội bộ HOAT_DONG; username/password đúng. | K49: mã cũ | L49: 1. Dọn mailbox/chuẩn bị authenticator. 2. Nhập username/password đúng. 3. Quan sát nguồn nhận mã. 4. Nhập mã theo Test Data. 5. Kiểm tra session, login audit và mailbox. | M49: 1-2. Qua bước mật khẩu. 3. ERR-DN-08; không tạo session. 4-5. Với case 02-04 chỉ chấm hành vi mã/session, không chấm kênh nhận mã; ghi bằng chứng kênh triển khai thực tế. | N49: Kênh triển khai thực tế; chờ BA chốt email hay authenticator | O49: Ghi Actual | P49: User khác | Q49: Session/JWT chỉ sinh sau 2FA; LOGIN audit; OTP/token không lộ log. | R49: — | U49: Not Run | X49: BR-AUTH-01 canonical yêu cầu email nhưng FR-VIII-20 vẫn ghi ứng dụng xác thực; build thiếu hoàn toàn yếu tố thứ hai là Fail nếu chưa có BA de-scope bằng văn bản.
A50: 49 | B50: EM-TK-2FA-05 | C50: [NGOÀI SRS] BR-AUTH-01 canonical srs-v3.5:5582,5596 vs FR-VIII-20 srs-fr-10:901-974; resend/rate-limit/TTL chưa đặc tả | D50: Đăng nhập 2FA | E50: P0 | F50: Security | G50: Gửi lại/rate-limit mã email 2FA | H50: Cán bộ nội bộ | I50: Màn đăng nhập Tier 1 | J50: Tài khoản nội bộ HOAT_DONG; username/password đúng. | K50: bấm gửi lại liên tục | L50: 1. Dọn mailbox/chuẩn bị authenticator. 2. Nhập username/password đúng. 3. Quan sát nguồn nhận mã. 4. Nhập mã theo Test Data. 5. Kiểm tra session, login audit và mailbox. | M50: 1-2. Qua bước mật khẩu. 3. [NGOÀI SRS] SRS không đặc tả gửi lại, rate-limit hoặc TTL cụ thể của mã 2FA. Ghi observation và escalate chủ sở hữu bảo mật; không log bug sai spec, không tự chấm N/A. 4-5. Ghi Actual, kênh triển khai và bằng chứng session/mailbox theo phạm vi case. | N50: Kênh triển khai thực tế; chờ BA chốt email hay authenticator | O50: Ghi Actual | P50: User khác | Q50: Session/JWT chỉ sinh sau 2FA; LOGIN audit; OTP/token không lộ log. | R50: — | U50: Not Run | X50: BR-AUTH-01 canonical yêu cầu email nhưng FR-VIII-20 vẫn ghi ứng dụng xác thực; build thiếu hoàn toàn yếu tố thứ hai là Fail nếu chưa có BA de-scope bằng văn bản.

Sheet 03_Doanh_nghiep
A1: STT | B1: Test Case ID | C1: TraceID (Mã SRS) | D1: Nhóm/Feature | E1: Priority | F1: Type | G1: Tên Test Case / Mục tiêu | H1: Tác nhân | I1: Điểm bắt đầu luồng | J1: Pre-conditions (Tiền đề) | K1: Test Data (Dữ liệu) | L1: Các bước thực hiện | M1: Kết quả mong đợi theo bước | N1: Nguồn địa chỉ nhận | O1: Expected To / CC | P1: Mailbox KHÔNG được nhận | Q1: UI / API / Queue / SMTP / Audit cần kiểm tra | R1: Post-condition / Cleanup | S1: Kết quả thực tế | T1: Evidence | U1: Trạng thái | V1: Bug ID | W1: Tester / Ngày | X1: Ghi chú
A2: 1 | B2: EM-DN-UI-01 | C2: FR-V.III-NEW-03 / SCR-V.III-03 / srs-fr-07:274-327,544-601 | D2: UI field verification | E2: P0 | F2: UI | G2: Kiểm tra email trên form CB tạo DN | H2: CB NV | I2: Doanh nghiệp > Thêm mới | J2: Có tài khoản đúng quyền; dữ liệu danh mục cần thiết đã seed. | K2: Không có. | L2: 1. Đăng nhập bằng đúng vai trò. 2. Mở màn hình theo điểm bắt đầu. 3. Đối chiếu từng trường, kiểu input, required/readonly và nút với SRS. 4. Kiểm tra điều kiện hiển thị/ẩn. 5. Kiểm tra tab order, label và thông báo validation khi bỏ trống. | M2: 1. Đăng nhập và phân quyền đúng. 2. Màn hình mở đúng. 3. Có đủ: Email doanh nghiệp là tùy chọn, input type email; chỉ MST + tên DN bắt buộc; không có password/username. 4. Nút/field chỉ hiện đúng điều kiện. 5. Required, readonly và validation đúng SRS. NEGATIVE: Không được có nút gửi mail kích hoạt; field trạng thái tài khoản. | N2: — | O2: — | P2: — | Q2: Kiểm tra màn hình không thay đổi dữ liệu và không phát sinh email; queue/audit chỉ khi có quyền. | R2: — | U2: Not Run
A3: 2 | B3: EM-DN-UI-02 | C3: FR-V.III-02 / SCR-V.III-02 / srs-fr-07:344-404,529 | D3: UI field verification | E3: P0 | F3: UI | G3: Kiểm tra email trên form DN cập nhật hồ sơ | H3: DN đăng nhập | I3: Hồ sơ doanh nghiệp > Cập nhật | J3: Có tài khoản đúng quyền; dữ liệu danh mục cần thiết đã seed. | K3: Không có. | L3: 1. Đăng nhập bằng đúng vai trò. 2. Mở màn hình theo điểm bắt đầu. 3. Đối chiếu từng trường, kiểu input, required/readonly và nút với SRS. 4. Kiểm tra điều kiện hiển thị/ẩn. 5. Kiểm tra tab order, label và thông báo validation khi bỏ trống. | M3: 1. Đăng nhập và phân quyền đúng. 2. Màn hình mở đúng. 3. Có đủ: Email liên hệ là field tự cập nhật, tùy chọn, validate format; không OTP. 4. Nút/field chỉ hiện đúng điều kiện. 5. Required, readonly và validation đúng SRS. | N3: — | O3: — | P3: — | Q3: Kiểm tra màn hình không thay đổi dữ liệu và không phát sinh email; queue/audit chỉ khi có quyền. | R3: — | U3: Not Run
A4: 3 | B4: EM-DN-UI-03 | C4: FR-VIII-22 / SCR-VIII-08 | D4: UI field verification | E4: P0 | F4: UI | G4: Phân biệt một ô email khi DN tự đăng ký | H4: DN chưa có TK | I4: Đăng nhập > Đăng ký DN | J4: Có tài khoản đúng quyền; dữ liệu danh mục cần thiết đã seed. | K4: Không có. | L4: 1. Đăng nhập bằng đúng vai trò. 2. Mở màn hình theo điểm bắt đầu. 3. Đối chiếu từng trường, kiểu input, required/readonly và nút với SRS. 4. Kiểm tra điều kiện hiển thị/ẩn. 5. Kiểm tra tab order, label và thông báo validation khi bỏ trống. | M4: 1. Đăng nhập và phân quyền đúng. 2. Màn hình mở đúng. 3. Có đủ: một ô email bắt buộc; không có hai field 'Email tài khoản'/'Email liên hệ'; tooltip giải thích đồng bộ ban đầu. 4. Nút/field chỉ hiện đúng điều kiện. 5. Required, readonly và validation đúng SRS. | N4: — | O4: — | P4: — | Q4: Kiểm tra màn hình không thay đổi dữ liệu và không phát sinh email; queue/audit chỉ khi có quyền. | R4: — | U4: Not Run
A5: 4 | B5: EM-DN-VAL-01 | C5: FR-V.III-NEW-03; DOANH_NGHIEP.email N | D5: Email validation | E5: P0 | F5: Negative/Edge | G5: CB tạo DN để trống email | H5: CB NV | I5: Doanh nghiệp > Thêm mới | J5: Đang ở form có trường email; ghi nhận số bản ghi hiển thị và inbox trước test. | K5: MST/tên hợp lệ; email rỗng | L5: 1. Mở form. 2. Nhập đầy đủ các trường khác hợp lệ. 3. Nhập email theo Test Data. 4. Bấm Lưu/Đăng ký. 5. Reload màn hình, kiểm tra UI/API response và inbox. | M5: 1-3. Form nhận đúng dữ liệu. 4. Cho tạo DOANH_NGHIEP; không tạo TK/mail. 5. Reload: email được lưu đúng; UI/API hiển thị đúng giá trị và chỉ phát sinh email nếu workflow của thao tác yêu cầu. | N5: Field email đang kiểm tra | O5: Không gửi mail nếu validation thất bại | P5: Tất cả mailbox test khi validation thất bại | Q5: Kiểm tra UI/API response, số bản ghi hiển thị và Gmail; queue/audit chỉ khi có quyền. | R5: — | U5: Not Run
A6: 5 | B6: EM-DN-VAL-02 | C6: FR-V.III-NEW-03 Inputs email | D6: Email validation | E6: P0 | F6: Negative/Edge | G6: CB tạo DN với email hợp lệ | H6: CB NV | I6: Doanh nghiệp > Thêm mới | J6: Đang ở form có trường email; ghi nhận số bản ghi hiển thị và inbox trước test. | K6: diupt01+uat-em-dn-val-02@gmail.com | L6: 1. Mở form. 2. Nhập đầy đủ các trường khác hợp lệ. 3. Nhập email theo Test Data. 4. Bấm Lưu/Đăng ký. 5. Reload màn hình, kiểm tra UI/API response và inbox. | M6: 1-3. Form nhận đúng dữ liệu. 4. Lưu vào DOANH_NGHIEP.email; không gửi mail. 5. Reload: email được lưu đúng; UI/API hiển thị đúng giá trị và chỉ phát sinh email nếu workflow của thao tác yêu cầu. | N6: Field email đang kiểm tra | O6: Không gửi mail nếu validation thất bại | P6: Tất cả mailbox test khi validation thất bại | Q6: Kiểm tra UI/API response, số bản ghi hiển thị và Gmail; queue/audit chỉ khi có quyền. | R6: — | U6: Not Run
A7: 6 | B7: EM-DN-VAL-03 | C7: FR-V.III-NEW-03 Inputs email | D7: Email validation | E7: P0 | F7: Negative/Edge | G7: CB tạo DN với email sai format | H7: CB NV | I7: Doanh nghiệp > Thêm mới | J7: Đang ở form có trường email; ghi nhận số bản ghi hiển thị và inbox trước test. | K7: dn-contact.example.test | L7: 1. Mở form. 2. Nhập đầy đủ các trường khác hợp lệ. 3. Nhập email theo Test Data. 4. Bấm Lưu/Đăng ký. 5. Reload màn hình, kiểm tra UI/API response và inbox. | M7: 1-3. Form nhận đúng dữ liệu. 4. Từ chối format; không tạo DN/TK/mail. 5. Reload: số bản ghi hiển thị không đổi, form không đóng/reset, không tạo token/job/email. | N7: Field email đang kiểm tra | O7: Không gửi mail nếu validation thất bại | P7: Tất cả mailbox test khi validation thất bại | Q7: Kiểm tra UI/API response, số bản ghi hiển thị và Gmail; queue/audit chỉ khi có quyền. | R7: — | U7: Not Run
A8: 7 | B8: EM-DN-VAL-04 | C8: BR-AUTH-EMAIL-01 | D8: Email validation | E8: P0 | F8: Negative/Edge | G8: Hai DN dùng chung email liên hệ | H8: CB NV | I8: Doanh nghiệp > Thêm mới | J8: Đang ở form có trường email; ghi nhận số bản ghi hiển thị và inbox trước test. | K8: Email đã ở DOANH_NGHIEP A, dùng cho DN B | L8: 1. Mở form. 2. Nhập đầy đủ các trường khác hợp lệ. 3. Nhập email theo Test Data. 4. Bấm Lưu/Đăng ký. 5. Reload màn hình, kiểm tra UI/API response và inbox. | M8: 1-3. Form nhận đúng dữ liệu. 4. Cho phép; DOANH_NGHIEP.email không UNIQUE. 5. Reload: email được lưu đúng; UI/API hiển thị đúng giá trị và chỉ phát sinh email nếu workflow của thao tác yêu cầu. | N8: Field email đang kiểm tra | O8: Không gửi mail nếu validation thất bại | P8: Tất cả mailbox test khi validation thất bại | Q8: Kiểm tra UI/API response, số bản ghi hiển thị và Gmail; queue/audit chỉ khi có quyền. | R8: — | U8: Not Run
A9: 8 | B9: EM-DN-VAL-05 | C9: BR-AUTH-EMAIL-01 | D9: Email validation | E9: P0 | F9: Negative/Edge | G9: Email DN trùng email tài khoản người khác khi CB tạo | H9: CB NV | I9: Doanh nghiệp > Thêm mới | J9: Đang ở form có trường email; ghi nhận số bản ghi hiển thị và inbox trước test. | K9: Email đã ở TAI_KHOAN của TVV | L9: 1. Mở form. 2. Nhập đầy đủ các trường khác hợp lệ. 3. Nhập email theo Test Data. 4. Bấm Lưu/Đăng ký. 5. Reload màn hình, kiểm tra UI/API response và inbox. | M9: 1-3. Form nhận đúng dữ liệu. 4. Cho phép vì đây là DOANH_NGHIEP.email và luồng không tạo TK. 5. Reload: email được lưu đúng; UI/API hiển thị đúng giá trị và chỉ phát sinh email nếu workflow của thao tác yêu cầu. | N9: Field email đang kiểm tra | O9: Không gửi mail nếu validation thất bại | P9: Tất cả mailbox test khi validation thất bại | Q9: Kiểm tra UI/API response, số bản ghi hiển thị và Gmail; queue/audit chỉ khi có quyền. | R9: — | U9: Not Run
A10: 9 | B10: EM-DN-UPD-01 | C10: FR-V.III-02 / BR-AUTH-EMAIL-01 | D10: Cập nhật email liên hệ DN | E10: P0 | F10: Workflow/Negative | G10: Đổi email liên hệ DN không đổi email tài khoản | H10: DN hoặc CB NV đúng quyền | I10: Chi tiết DN > Chỉnh sửa | J10: Có DN/TK theo Test Data; ghi giá trị trước test. | K10: TK=MB_TK_CURRENT; DN old=MB_DN_CONTACT → new=diupt01+uat-em-dn-upd-01-new@gmail.com | L10: 1. Ghi email TK/DN trước test. 2. Mở form chỉnh sửa. 3. Đổi email theo Test Data. 4. Lưu và reload. 5. Kiểm tra UI/API, inbox và audit. | M10: 1-4. DOANH_NGHIEP.email=new; TAI_KHOAN.email vẫn là MB_TK_CURRENT; không OTP. 5. Không sinh OTP/email kích hoạt; audit update nếu SRS/framework yêu cầu. | N10: DOANH_NGHIEP.email | O10: Không gửi mail do thao tác đổi | P10: Tất cả mailbox | Q10: DOANH_NGHIEP.email; TAI_KHOAN.email không bị side-effect; queue +0; audit diff. | R10: — | U10: Not Run
A11: 10 | B11: EM-DN-UPD-02 | C11: FR-V.III-02 / BR-AUTH-EMAIL-01 | D11: Cập nhật email liên hệ DN | E11: P0 | F11: Workflow/Negative | G11: Đổi email DN thành giá trị đang được DN khác dùng | H11: DN hoặc CB NV đúng quyền | I11: Chi tiết DN > Chỉnh sửa | J11: Có DN/TK theo Test Data; ghi giá trị trước test. | K11: new=diupt01+uat-em-dn-upd-02-shared@gmail.com | L11: 1. Ghi email TK/DN trước test. 2. Mở form chỉnh sửa. 3. Đổi email theo Test Data. 4. Lưu và reload. 5. Kiểm tra UI/API, inbox và audit. | M11: 1-4. Cho phép; cả hai DN dùng chung email. 5. Không sinh OTP/email kích hoạt; audit update nếu SRS/framework yêu cầu. | N11: DOANH_NGHIEP.email | O11: Không gửi mail do thao tác đổi | P11: Tất cả mailbox | Q11: DOANH_NGHIEP.email; TAI_KHOAN.email không bị side-effect; queue +0; audit diff. | R11: — | U11: Not Run
A12: 11 | B12: EM-DN-UPD-03 | C12: FR-V.III-02 / BR-AUTH-EMAIL-01 | D12: Cập nhật email liên hệ DN | E12: P0 | F12: Workflow/Negative | G12: Xóa email liên hệ tùy chọn | H12: DN hoặc CB NV đúng quyền | I12: Chi tiết DN > Chỉnh sửa | J12: Có DN/TK theo Test Data; ghi giá trị trước test. | K12: new=rỗng | L12: 1. Ghi email TK/DN trước test. 2. Mở form chỉnh sửa. 3. Đổi email theo Test Data. 4. Lưu và reload. 5. Kiểm tra UI/API, inbox và audit. | M12: 1-4. Cho lưu nếu các field bắt buộc khác còn hợp lệ; TK email không đổi. 5. Không sinh OTP/email kích hoạt; audit update nếu SRS/framework yêu cầu. | N12: DOANH_NGHIEP.email | O12: Không gửi mail do thao tác đổi | P12: Tất cả mailbox | Q12: DOANH_NGHIEP.email; TAI_KHOAN.email không bị side-effect; queue +0; audit diff. | R12: — | U12: Not Run
A13: 12 | B13: EM-DN-UPD-04 | C13: FR-V.III-02 / BR-AUTH-EMAIL-01 | D13: Cập nhật email liên hệ DN | E13: P0 | F13: Workflow/Negative | G13: Email DN sai format khi cập nhật | H13: DN hoặc CB NV đúng quyền | I13: Chi tiết DN > Chỉnh sửa | J13: Có DN/TK theo Test Data; ghi giá trị trước test. | K13: new=bad-email | L13: 1. Ghi email TK/DN trước test. 2. Mở form chỉnh sửa. 3. Đổi email theo Test Data. 4. Lưu và reload. 5. Kiểm tra UI/API, inbox và audit. | M13: 1-4. Từ chối; old email giữ nguyên; không mail/OTP. 5. Không sinh OTP/email kích hoạt; audit update nếu SRS/framework yêu cầu. | N13: DOANH_NGHIEP.email | O13: Không gửi mail do thao tác đổi | P13: Tất cả mailbox | Q13: DOANH_NGHIEP.email; TAI_KHOAN.email không bị side-effect; queue +0; audit diff. | R13: — | U13: Not Run
... A30: 29 | B30: EM-DN-CLAIM-06 | C30: FR-VIII-26 / Concurrency | D30: DN Claim Flow | E30: P0 | F30: Workflow/Negative/Concurrency | G30: Hai yêu cầu Claim đồng thời | H30: DN | I30: Đăng nhập > Quên mật khẩu | J30: DN tồn tại chưa có TK; hai request MST cùng lúc. | K30: MST 0100000306 | L30: 1. Dọn inbox; ghi count DN/TK/token/queue và liên kết hiện tại. 2. Nhập MST vào một ô Tên đăng nhập. 3. Bấm gửi link. 4. Kiểm tra UI, UI/API và inbox. 5. Mở link, đặt mật khẩu nếu nhận được. 6. Đăng nhập và kiểm tra hồ sơ/quyền/audit. | M30: Chỉ một TAI_KHOAN liên kết DN và một role DN; không duplicate key/500. Chính sách số mail/token phải nhất quán; chỉ token được coi hiệu lực theo quy tắc hệ thống. | N30: DOANH_NGHIEP.email | O30: To: DOANH_NGHIEP.email cho claim mới; TAI_KHOAN.email nếu TK đã có | P30: Email DN/TK khác; email cũ sau khi đã cập nhật | Q30: TAI_KHOAN count/link DN/role DN; token vĩnh viễn một lần cho CHO_KICH_HOAT; queue/SMTP; AUDIT_LOG DN_CLAIM. | R30: Thu hồi token; vô hiệu hóa TK claim fixture nếu cần. | U30: Not Run

Sheet 04_Notification
A1: STT | B1: Test Case ID | C1: TraceID (Mã SRS) | D1: Nhóm/Feature | E1: Priority | F1: Type | G1: Tên Test Case / Mục tiêu | H1: Tác nhân | I1: Điểm bắt đầu luồng | J1: Pre-conditions (Tiền đề) | K1: Test Data (Dữ liệu) | L1: Các bước thực hiện | M1: Kết quả mong đợi theo bước | N1: Nguồn địa chỉ nhận | O1: Expected To / CC | P1: Mailbox KHÔNG được nhận | Q1: UI / API / Queue / SMTP / Audit cần kiểm tra | R1: Post-condition / Cleanup | S1: Kết quả thực tế | T1: Evidence | U1: Trạng thái | V1: Bug ID | W1: Tester / Ngày | X1: Ghi chú
A2: 1 | B2: EM-NOT-HDD-01 | C2: FR-II-05 / srs-fr-02:510 | D2: Hỏi đáp | E2: P0 | F2: Workflow | G2: Phân công hỏi đáp | H2: CB NV có quyền | I2: Chi tiết hỏi đáp > Phân công | J2: Hỏi đáp TIEP_NHAN; người xử lý hợp lệ. | K2: Mã HĐ; người được phân công Fixture DEV đã gắn email: Lane TW: cbnv_tw_01=diupt01+cb-nv-a@gmail.com; cbnv_tw_02=diupt01+cb-nv-a-2@gmail.com; cbpd_tw_01=diupt01+cb-pd-a@gmail.com; mailbox âm khác đơn vị: cbnv_bn_01/cbpd_bn_01. | L2: 1. Xóa thư cũ; ghi nhận trạng thái hồ sơ và số chưa đọc trên chuông. 2. Đăng nhập đúng tác nhân, mở đúng hồ sơ ở trạng thái nguồn. 3. Thực hiện hành động trigger; không bấm lặp. 4. Reload chi tiết/danh sách và chờ email tối đa 5 phút. 5. Kiểm tra mailbox Expected To/CC và toàn bộ mailbox âm. 6. Đối chiếu chuông với Gmail; kiểm queue/SMTP log và audit nếu có quyền. 7. Nếu SRS quy định in-app: đăng nhập từng tài khoản nhận, mở chuông và trang Xem tất cả thông báo; kiểm số chưa đọc, nội dung, thời gian, link, trạng thái đã đọc; đăng nhập tài khoản âm để kiểm không nhìn thấy. Người nhận chưa có tài khoản không kiểm chuông. | M2: 1. Baseline sạch, không nhầm email cũ. 2. Hồ sơ và quyền đúng tiền đề. 3. Hỏi đáp → DANG_XU_LY, người xử lý được set. 4. UI phản ánh trạng thái mới. 5. Chỉ đúng người nhận nhận email; email chứa mã/nội dung phân công và link hồ sơ; đúng 1 email/người/sự kiện. 6. Gmail và chuông đúng với kênh được cấu hình; queue/audit khớp nếu có quyền. 7. Với đối tượng được SRS chỉ định nhận in-app: đúng người nhận thấy đúng một thông báo mới trên chuông; số chưa đọc, nội dung, thời gian, link và trạng thái đã đọc đúng; tài khoản khác không thấy. Người chưa có tài khoản chỉ nhận email và không có thông báo trên ứng dụng. | N2: TAI_KHOAN.email người được phân công | O2: To: người được phân công | P2: CB khác/đơn vị khác/người gửi | Q2: Kiểm tra trạng thái trên UI/API, Gmail và chuông của đúng người nhận/tài khoản âm; queue/SMTP/audit chỉ khi có quyền. | R2: Khôi phục fixture hoặc dùng hồ sơ mới cho case kế tiếp; lưu message-id và ảnh inbox/log. | U2: Not Run
A3: 2 | B3: EM-NOT-HDD-02 | C3: BR-NOTIF-01 trigger trình duyệt; srs-fr-02:1175 | D3: Hỏi đáp | E3: P0 | F3: Workflow | G3: Gửi phản hồi để trình phê duyệt | H3: CB NV xử lý | I3: Chi tiết hỏi đáp > Gửi phản hồi + Đã trả lời | J3: Hỏi đáp DANG_XU_LY; phản hồi hợp lệ. | K3: CB PD cùng đơn vị Fixture DEV đã gắn email: Lane TW: cbnv_tw_01=diupt01+cb-nv-a@gmail.com; cbnv_tw_02=diupt01+cb-nv-a-2@gmail.com; cbpd_tw_01=diupt01+cb-pd-a@gmail.com; mailbox âm khác đơn vị: cbnv_bn_01/cbpd_bn_01. | L3: 1. Xóa thư cũ; ghi nhận trạng thái hồ sơ và số chưa đọc trên chuông. 2. Đăng nhập đúng tác nhân, mở đúng hồ sơ ở trạng thái nguồn. 3. Thực hiện hành động trigger; không bấm lặp. 4. Reload chi tiết/danh sách và chờ email tối đa 5 phút. 5. Kiểm tra mailbox Expected To/CC và toàn bộ mailbox âm. 6. Đối chiếu chuông với Gmail; kiểm queue/SMTP log và audit nếu có quyền. 7. Nếu SRS quy định in-app: đăng nhập từng tài khoản nhận, mở chuông và trang Xem tất cả thông báo; kiểm số chưa đọc, nội dung, thời gian, link, trạng thái đã đọc; đăng nhập tài khoản âm để kiểm không nhìn thấy. Người nhận chưa có tài khoản không kiểm chuông. | M3: 1. Baseline sạch, không nhầm email cũ. 2. Hồ sơ và quyền đúng tiền đề. 3. Hỏi đáp → CHO_PHE_DUYET. 4. UI phản ánh trạng thái mới. 5. Chỉ đúng người nhận nhận email; email nêu hồ sơ chờ duyệt; ≤5 phút; đúng 1 email/người/sự kiện. 6. Gmail và chuông đúng với kênh được cấu hình; queue/audit khớp nếu có quyền. 7. Với đối tượng được SRS chỉ định nhận in-app: đúng người nhận thấy đúng một thông báo mới trên chuông; số chưa đọc, nội dung, thời gian, link và trạng thái đã đọc đúng; tài khoản khác không thấy. Người chưa có tài khoản chỉ nhận email và không có thông báo trên ứng dụng. | N3: TAI_KHOAN.email CB PD cùng đơn vị | O3: To: CB PD cùng đơn vị | P3: CB PD khác đơn vị/cấp không phù hợp | Q3: Kiểm tra trạng thái trên UI/API, Gmail và chuông của đúng người nhận/tài khoản âm; queue/SMTP/audit chỉ khi có quyền. | R3: Khôi phục fixture hoặc dùng hồ sơ mới cho case kế tiếp; lưu message-id và ảnh inbox/log. | U3: Not Run
